Copied /home/keenan/Dev/etr_case_generator/datasets/largeset_open_ended.jsonl to datasets/etr_for_lm_eval.jsonl
Configuration:
  OpenRouter Model: openai/chatgpt-4o-latest
  Evaluation harness path: /home/keenan/Dev/lm-evaluation-harness/
  Include path: /home/keenan/Dev/etr_case_generator/
  Task: etr_problems_open_ended

2025-04-25:20:30:58,551 WARNING  [openai_completions.py:108] chat-completions endpoint requires the `--apply_chat_template` flag.
Generating train split: 0 examples [00:00, ? examples/s]Generating train split: 400 examples [00:00, 11733.96 examples/s]
2025-04-25:20:30:59,506 WARNING  [evaluator.py:270] Overwriting default num_fewshot of etr_problems_open_ended from None to 0
2025-04-25:20:30:59,506 WARNING  [evaluator.py:406] Chat template formatting change affects loglikelihood and multiple-choice tasks. See docs/chat-template-readme.md for details.
  0%|          | 0/400 [00:00<?, ?it/s] 95%|█████████▍| 379/400 [00:00<00:00, 3783.31it/s]100%|██████████| 400/400 [00:00<00:00, 3737.80it/s]
Requesting API:   0%|          | 0/400 [00:00<?, ?it/s]2025-04-25:20:30:59,790 WARNING  [api_models.py:287] Cannot determine EOS string to pass to stop sequence. Manually set by passing `eos_string` to model_args.
Traceback (most recent call last):
  File "/home/keenan/.local/pipx/venvs/lm-eval/lib/python3.12/site-packages/urllib3/connection.py", line 199, in _new_conn
    sock = connection.create_connection(
           ^^^^^^^^^^^^^^^^^^^^^^^^^^^^^
  File "/home/keenan/.local/pipx/venvs/lm-eval/lib/python3.12/site-packages/urllib3/util/connection.py", line 60, in create_connection
    for res in socket.getaddrinfo(host, port, family, socket.SOCK_STREAM):
               ^^^^^^^^^^^^^^^^^^^^^^^^^^^^^^^^^^^^^^^^^^^^^^^^^^^^^^^^^^
  File "/usr/lib/python3.12/socket.py", line 963, in getaddrinfo
    for res in _socket.getaddrinfo(host, port, family, type, proto, flags):
               ^^^^^^^^^^^^^^^^^^^^^^^^^^^^^^^^^^^^^^^^^^^^^^^^^^^^^^^^^^^
socket.gaierror: [Errno -2] Name or service not known

The above exception was the direct cause of the following exception:

Traceback (most recent call last):
  File "/home/keenan/.local/pipx/venvs/lm-eval/lib/python3.12/site-packages/urllib3/connectionpool.py", line 789, in urlopen
    response = self._make_request(
               ^^^^^^^^^^^^^^^^^^^
  File "/home/keenan/.local/pipx/venvs/lm-eval/lib/python3.12/site-packages/urllib3/connectionpool.py", line 490, in _make_request
    raise new_e
  File "/home/keenan/.local/pipx/venvs/lm-eval/lib/python3.12/site-packages/urllib3/connectionpool.py", line 466, in _make_request
    self._validate_conn(conn)
  File "/home/keenan/.local/pipx/venvs/lm-eval/lib/python3.12/site-packages/urllib3/connectionpool.py", line 1095, in _validate_conn
    conn.connect()
  File "/home/keenan/.local/pipx/venvs/lm-eval/lib/python3.12/site-packages/urllib3/connection.py", line 693, in connect
    self.sock = sock = self._new_conn()
                       ^^^^^^^^^^^^^^^^
  File "/home/keenan/.local/pipx/venvs/lm-eval/lib/python3.12/site-packages/urllib3/connection.py", line 206, in _new_conn
    raise NameResolutionError(self.host, self, e) from e
urllib3.exceptions.NameResolutionError: <urllib3.connection.HTTPSConnection object at 0x77aeee128f20>: Failed to resolve 'openrouter.ai' ([Errno -2] Name or service not known)

The above exception was the direct cause of the following exception:

Traceback (most recent call last):
  File "/home/keenan/.local/pipx/venvs/lm-eval/lib/python3.12/site-packages/requests/adapters.py", line 667, in send
    resp = conn.urlopen(
           ^^^^^^^^^^^^^
  File "/home/keenan/.local/pipx/venvs/lm-eval/lib/python3.12/site-packages/urllib3/connectionpool.py", line 843, in urlopen
    retries = retries.increment(
              ^^^^^^^^^^^^^^^^^^
  File "/home/keenan/.local/pipx/venvs/lm-eval/lib/python3.12/site-packages/urllib3/util/retry.py", line 519, in increment
    raise MaxRetryError(_pool, url, reason) from reason  # type: ignore[arg-type]
    ^^^^^^^^^^^^^^^^^^^^^^^^^^^^^^^^^^^^^^^^^^^^^^^^^^^
urllib3.exceptions.MaxRetryError: HTTPSConnectionPool(host='openrouter.ai', port=443): Max retries exceeded with url: /api/v1/chat/completions (Caused by NameResolutionError("<urllib3.connection.HTTPSConnection object at 0x77aeee128f20>: Failed to resolve 'openrouter.ai' ([Errno -2] Name or service not known)"))

During handling of the above exception, another exception occurred:

Traceback (most recent call last):
  File "/home/keenan/.local/bin/lm_eval", line 8, in <module>
    sys.exit(cli_evaluate())
             ^^^^^^^^^^^^^^
  File "/home/keenan/Dev/lm-evaluation-harness/lm_eval/__main__.py", line 382, in cli_evaluate
    results = evaluator.simple_evaluate(
              ^^^^^^^^^^^^^^^^^^^^^^^^^^
  File "/home/keenan/Dev/lm-evaluation-harness/lm_eval/utils.py", line 397, in _wrapper
    return fn(*args, **kwargs)
           ^^^^^^^^^^^^^^^^^^^
  File "/home/keenan/Dev/lm-evaluation-harness/lm_eval/evaluator.py", line 303, in simple_evaluate
    results = evaluate(
              ^^^^^^^^^
  File "/home/keenan/Dev/lm-evaluation-harness/lm_eval/utils.py", line 397, in _wrapper
    return fn(*args, **kwargs)
           ^^^^^^^^^^^^^^^^^^^
  File "/home/keenan/Dev/lm-evaluation-harness/lm_eval/evaluator.py", line 507, in evaluate
    resps = getattr(lm, reqtype)(cloned_reqs)
            ^^^^^^^^^^^^^^^^^^^^^^^^^^^^^^^^^
  File "/home/keenan/Dev/lm-evaluation-harness/lm_eval/models/api_models.py", line 598, in generate_until
    outputs = retry(
              ^^^^^^
  File "/home/keenan/.local/pipx/venvs/lm-eval/lib/python3.12/site-packages/tenacity/__init__.py", line 336, in wrapped_f
    return copy(f, *args, **kw)
           ^^^^^^^^^^^^^^^^^^^^
  File "/home/keenan/.local/pipx/venvs/lm-eval/lib/python3.12/site-packages/tenacity/__init__.py", line 475, in __call__
    do = self.iter(retry_state=retry_state)
         ^^^^^^^^^^^^^^^^^^^^^^^^^^^^^^^^^^
  File "/home/keenan/.local/pipx/venvs/lm-eval/lib/python3.12/site-packages/tenacity/__init__.py", line 376, in iter
    result = action(retry_state)
             ^^^^^^^^^^^^^^^^^^^
  File "/home/keenan/.local/pipx/venvs/lm-eval/lib/python3.12/site-packages/tenacity/__init__.py", line 418, in exc_check
    raise retry_exc.reraise()
          ^^^^^^^^^^^^^^^^^^^
  File "/home/keenan/.local/pipx/venvs/lm-eval/lib/python3.12/site-packages/tenacity/__init__.py", line 185, in reraise
    raise self.last_attempt.result()
          ^^^^^^^^^^^^^^^^^^^^^^^^^^
  File "/usr/lib/python3.12/concurrent/futures/_base.py", line 449, in result
    return self.__get_result()
           ^^^^^^^^^^^^^^^^^^^
  File "/usr/lib/python3.12/concurrent/futures/_base.py", line 401, in __get_result
    raise self._exception
  File "/home/keenan/.local/pipx/venvs/lm-eval/lib/python3.12/site-packages/tenacity/__init__.py", line 478, in __call__
    result = fn(*args, **kwargs)
             ^^^^^^^^^^^^^^^^^^^
  File "/home/keenan/Dev/lm-evaluation-harness/lm_eval/models/api_models.py", line 360, in model_call
    response = requests.post(
               ^^^^^^^^^^^^^^
  File "/home/keenan/.local/pipx/venvs/lm-eval/lib/python3.12/site-packages/requests/api.py", line 115, in post
    return request("post", url, data=data, json=json, **kwargs)
           ^^^^^^^^^^^^^^^^^^^^^^^^^^^^^^^^^^^^^^^^^^^^^^^^^^^^
  File "/home/keenan/.local/pipx/venvs/lm-eval/lib/python3.12/site-packages/requests/api.py", line 59, in request
    return session.request(method=method, url=url, **kwargs)
           ^^^^^^^^^^^^^^^^^^^^^^^^^^^^^^^^^^^^^^^^^^^^^^^^^
  File "/home/keenan/.local/pipx/venvs/lm-eval/lib/python3.12/site-packages/requests/sessions.py", line 589, in request
    resp = self.send(prep, **send_kwargs)
           ^^^^^^^^^^^^^^^^^^^^^^^^^^^^^^
  File "/home/keenan/.local/pipx/venvs/lm-eval/lib/python3.12/site-packages/requests/sessions.py", line 703, in send
    r = adapter.send(request, **kwargs)
        ^^^^^^^^^^^^^^^^^^^^^^^^^^^^^^^
  File "/home/keenan/.local/pipx/venvs/lm-eval/lib/python3.12/site-packages/requests/adapters.py", line 700, in send
    raise ConnectionError(e, request=request)
requests.exceptions.ConnectionError: HTTPSConnectionPool(host='openrouter.ai', port=443): Max retries exceeded with url: /api/v1/chat/completions (Caused by NameResolutionError("<urllib3.connection.HTTPSConnection object at 0x77aeee128f20>: Failed to resolve 'openrouter.ai' ([Errno -2] Name or service not known)"))
Requesting API:   0%|          | 0/400 [13:36:23<?, ?it/s]
Restored original OpenAI API key
